Traceback (most recent call last):
  File "C:\Users\vkoul\Anaconda3\lib\site-packages\jupyter_cache\executors\utils.py", line 51, in single_nb_execution
    executenb(
  File "C:\Users\vkoul\Anaconda3\lib\site-packages\nbclient\client.py", line 1204, in execute
    return NotebookClient(nb=nb, resources=resources, km=km, **kwargs).execute()
  File "C:\Users\vkoul\Anaconda3\lib\site-packages\nbclient\util.py", line 84, in wrapped
    return just_run(coro(*args, **kwargs))
  File "C:\Users\vkoul\Anaconda3\lib\site-packages\nbclient\util.py", line 62, in just_run
    return loop.run_until_complete(coro)
  File "C:\Users\vkoul\Anaconda3\lib\asyncio\base_events.py", line 647, in run_until_complete
    return future.result()
  File "C:\Users\vkoul\Anaconda3\lib\site-packages\nbclient\client.py", line 663, in async_execute
    await self.async_execute_cell(
  File "C:\Users\vkoul\Anaconda3\lib\site-packages\nbclient\client.py", line 965, in async_execute_cell
    await self._check_raise_for_error(cell, cell_index, exec_reply)
  File "C:\Users\vkoul\Anaconda3\lib\site-packages\nbclient\client.py", line 862, in _check_raise_for_error
    raise CellExecutionError.from_cell_and_msg(cell, exec_reply_content)
nbclient.exceptions.CellExecutionError: An error occurred while executing the following cell:
------------------
df["survived_mapped"].value_counts()
------------------

[1;31m---------------------------------------------------------------------------[0m
[1;31mKeyError[0m                                  Traceback (most recent call last)
File [1;32m~\Anaconda3\lib\site-packages\pandas\core\indexes\base.py:3629[0m, in [0;36mIndex.get_loc[1;34m(self, key, method, tolerance)[0m
[0;32m   3628[0m [38;5;28;01mtry[39;00m:
[1;32m-> 3629[0m     [38;5;28;01mreturn[39;00m [38;5;28;43mself[39;49m[38;5;241;43m.[39;49m[43m_engine[49m[38;5;241;43m.[39;49m[43mget_loc[49m[43m([49m[43mcasted_key[49m[43m)[49m
[0;32m   3630[0m [38;5;28;01mexcept[39;00m [38;5;167;01mKeyError[39;00m [38;5;28;01mas[39;00m err:

File [1;32m~\Anaconda3\lib\site-packages\pandas\_libs\index.pyx:136[0m, in [0;36mpandas._libs.index.IndexEngine.get_loc[1;34m()[0m

File [1;32m~\Anaconda3\lib\site-packages\pandas\_libs\index.pyx:163[0m, in [0;36mpandas._libs.index.IndexEngine.get_loc[1;34m()[0m

File [1;32mpandas\_libs\hashtable_class_helper.pxi:5198[0m, in [0;36mpandas._libs.hashtable.PyObjectHashTable.get_item[1;34m()[0m

File [1;32mpandas\_libs\hashtable_class_helper.pxi:5206[0m, in [0;36mpandas._libs.hashtable.PyObjectHashTable.get_item[1;34m()[0m

[1;31mKeyError[0m: 'survived_mapped'

The above exception was the direct cause of the following exception:

[1;31mKeyError[0m                                  Traceback (most recent call last)
Input [1;32mIn [66][0m, in [0;36m<cell line: 1>[1;34m()[0m
[1;32m----> 1[0m [43mdf[49m[43m[[49m[38;5;124;43m"[39;49m[38;5;124;43msurvived_mapped[39;49m[38;5;124;43m"[39;49m[43m][49m[38;5;241m.[39mvalue_counts()

File [1;32m~\Anaconda3\lib\site-packages\pandas\core\frame.py:3505[0m, in [0;36mDataFrame.__getitem__[1;34m(self, key)[0m
[0;32m   3503[0m [38;5;28;01mif[39;00m [38;5;28mself[39m[38;5;241m.[39mcolumns[38;5;241m.[39mnlevels [38;5;241m>[39m [38;5;241m1[39m:
[0;32m   3504[0m     [38;5;28;01mreturn[39;00m [38;5;28mself[39m[38;5;241m.[39m_getitem_multilevel(key)
[1;32m-> 3505[0m indexer [38;5;241m=[39m [38;5;28;43mself[39;49m[38;5;241;43m.[39;49m[43mcolumns[49m[38;5;241;43m.[39;49m[43mget_loc[49m[43m([49m[43mkey[49m[43m)[49m
[0;32m   3506[0m [38;5;28;01mif[39;00m is_integer(indexer):
[0;32m   3507[0m     indexer [38;5;241m=[39m [indexer]

File [1;32m~\Anaconda3\lib\site-packages\pandas\core\indexes\base.py:3631[0m, in [0;36mIndex.get_loc[1;34m(self, key, method, tolerance)[0m
[0;32m   3629[0m     [38;5;28;01mreturn[39;00m [38;5;28mself[39m[38;5;241m.[39m_engine[38;5;241m.[39mget_loc(casted_key)
[0;32m   3630[0m [38;5;28;01mexcept[39;00m [38;5;167;01mKeyError[39;00m [38;5;28;01mas[39;00m err:
[1;32m-> 3631[0m     [38;5;28;01mraise[39;00m [38;5;167;01mKeyError[39;00m(key) [38;5;28;01mfrom[39;00m [38;5;21;01merr[39;00m
[0;32m   3632[0m [38;5;28;01mexcept[39;00m [38;5;167;01mTypeError[39;00m:
[0;32m   3633[0m     [38;5;66;03m# If we have a listlike key, _check_indexing_error will raise[39;00m
[0;32m   3634[0m     [38;5;66;03m#  InvalidIndexError. Otherwise we fall through and re-raise[39;00m
[0;32m   3635[0m     [38;5;66;03m#  the TypeError.[39;00m
[0;32m   3636[0m     [38;5;28mself[39m[38;5;241m.[39m_check_indexing_error(key)

[1;31mKeyError[0m: 'survived_mapped'
KeyError: 'survived_mapped'

